Traceback (most recent call last):
  File "/usr/local/lib/python3.8/dist-packages/jupyter_cache/executors/utils.py", line 51, in single_nb_execution
    executenb(
  File "/usr/local/lib/python3.8/dist-packages/nbclient/client.py", line 1204, in execute
    return NotebookClient(nb=nb, resources=resources, km=km, **kwargs).execute()
  File "/usr/local/lib/python3.8/dist-packages/nbclient/util.py", line 84, in wrapped
    return just_run(coro(*args, **kwargs))
  File "/usr/local/lib/python3.8/dist-packages/nbclient/util.py", line 62, in just_run
    return loop.run_until_complete(coro)
  File "/usr/lib/python3.8/asyncio/base_events.py", line 616, in run_until_complete
    return future.result()
  File "/usr/local/lib/python3.8/dist-packages/nbclient/client.py", line 663, in async_execute
    await self.async_execute_cell(
  File "/usr/local/lib/python3.8/dist-packages/nbclient/client.py", line 965, in async_execute_cell
    await self._check_raise_for_error(cell, cell_index, exec_reply)
  File "/usr/local/lib/python3.8/dist-packages/nbclient/client.py", line 862, in _check_raise_for_error
    raise CellExecutionError.from_cell_and_msg(cell, exec_reply_content)
nbclient.exceptions.CellExecutionError: An error occurred while executing the following cell:
------------------
c = twint.Config()
c.Search = "prabowo"
c.Pandas = True
twint.run.Search(c)
------------------

[0;31m[0m
[0;31mAttributeError[0mTraceback (most recent call last)
[0;32m<ipython-input-3-01afe4f0dafb>[0m in [0;36m<module>[0;34m[0m
[0;32m----> 1[0;31m [0mc[0m [0;34m=[0m [0mtwint[0m[0;34m.[0m[0mConfig[0m[0;34m([0m[0;34m)[0m[0;34m[0m[0;34m[0m[0m
[0m[1;32m      2[0m [0mc[0m[0;34m.[0m[0mSearch[0m [0;34m=[0m [0;34m"prabowo"[0m[0;34m[0m[0;34m[0m[0m
[1;32m      3[0m [0mc[0m[0;34m.[0m[0mPandas[0m [0;34m=[0m [0;32mTrue[0m[0;34m[0m[0;34m[0m[0m
[1;32m      4[0m [0mtwint[0m[0;34m.[0m[0mrun[0m[0;34m.[0m[0mSearch[0m[0;34m([0m[0mc[0m[0;34m)[0m[0;34m[0m[0;34m[0m[0m

[0;31mAttributeError[0m: module 'twint' has no attribute 'Config'
AttributeError: module 'twint' has no attribute 'Config'

